Workbook

Sheet Dashboard
B1: DOWNTIME BY FACTOR
B2: FACTOR | C2: TOTAL MINUTES
A3: 6 | B3: =_xlfn.XLOOKUP(A3,'Downtime factors'!A7:A18,'Downtime factors'!B7:B18) -> Machine adjustment | C3: =_xlfn.XLOOKUP(A3,'Line downtime'!$B$2:$M$2,'Line downtime'!$B$42:$M$42) -> 332
A4: 7 | B4: =_xlfn.XLOOKUP(A4,'Downtime factors'!A8:A19,'Downtime factors'!B8:B19) -> Machine failure | C4: =_xlfn.XLOOKUP(A4,'Line downtime'!$B$2:$M$2,'Line downtime'!$B$42:$M$42) -> 254
A5: 4 | B5: =_xlfn.XLOOKUP(A5,'Downtime factors'!A5:A16,'Downtime factors'!B5:B16) -> Inventory shortage | C5: =_xlfn.XLOOKUP(A5,'Line downtime'!$B$2:$M$2,'Line downtime'!$B$42:$M$42) -> 225
A6: 2 | B6: =_xlfn.XLOOKUP(A6,'Downtime factors'!A3:A14,'Downtime factors'!B3:B14) -> Batch change | C6: =_xlfn.XLOOKUP(A6,'Line downtime'!$B$2:$M$2,'Line downtime'!$B$42:$M$42) -> 160
A7: 8 | B7: =_xlfn.XLOOKUP(A7,'Downtime factors'!A9:A20,'Downtime factors'!B9:B20) -> Batch coding error | C7: =_xlfn.XLOOKUP(A7,'Line downtime'!$B$2:$M$2,'Line downtime'!$B$42:$M$42) -> 145
A8: 12 | B8: =_xlfn.XLOOKUP(A8,'Downtime factors'!A13:A24,'Downtime factors'!B13:B24) -> Other | C8: =_xlfn.XLOOKUP(A8,'Line downtime'!$B$2:$M$2,'Line downtime'!$B$42:$M$42) -> 74
A9: 5 | B9: =_xlfn.XLOOKUP(A9,'Downtime factors'!A6:A17,'Downtime factors'!B6:B17) -> Product spill | C9: =_xlfn.XLOOKUP(A9,'Line downtime'!$B$2:$M$2,'Line downtime'!$B$42:$M$42) -> 57
A10: 10 | B10: =_xlfn.XLOOKUP(A10,'Downtime factors'!A11:A22,'Downtime factors'!B11:B22) -> Calibration error | C10: =_xlfn.XLOOKUP(A10,'Line downtime'!$B$2:$M$2,'Line downtime'!$B$42:$M$42) -> 49
A11: 3 | B11: =_xlfn.XLOOKUP(A11,'Downtime factors'!A4:A15,'Downtime factors'!B4:B15) -> Labeling error | C11: =_xlfn.XLOOKUP(A11,'Line downtime'!$B$2:$M$2,'Line downtime'!$B$42:$M$42) -> 42
A12: 11 | B12: =_xlfn.XLOOKUP(A12,'Downtime factors'!A12:A23,'Downtime factors'!B12:B23) -> Label switch | C12: =_xlfn.XLOOKUP(A12,'Line downtime'!$B$2:$M$2,'Line downtime'!$B$42:$M$42) -> 33
A13: 9 | B13: =_xlfn.XLOOKUP(A13,'Downtime factors'!A10:A21,'Downtime factors'!B10:B21) -> Conveyor belt jam | C13: =_xlfn.XLOOKUP(A13,'Line downtime'!$B$2:$M$2,'Line downtime'!$B$42:$M$42) -> 17
A14: 1 | B14: =_xlfn.XLOOKUP(A14,'Downtime factors'!A2:A13,'Downtime factors'!B2:B13) -> Emergency stop | C14: =_xlfn.XLOOKUP(A14,'Line downtime'!$B$2:$M$2,'Line downtime'!$B$42:$M$42) -> 0
D18: 2 | E18: 3 | F18: 4 | G18: 5 | H18: 6 | I18: 7 | J18: 8 | K18: 9 | L18: 10 | M18: 11 | N18: 12
D19: =_xlfn.XLOOKUP(D18,'Downtime factors'!$A$2:$A$13,'Downtime factors'!$B$2:$B$13) -> Batch change | E19: =_xlfn.XLOOKUP(E18,'Downtime factors'!$A$2:$A$13,'Downtime factors'!$B$2:$B$13) -> Labeling error | F19: =_xlfn.XLOOKUP(F18,'Downtime factors'!$A$2:$A$13,'Downtime factors'!$B$2:$B$13) -> Inventory shortage | G19: =_xlfn.XLOOKUP(G18,'Downtime factors'!$A$2:$A$13,'Downtime factors'!$B$2:$B$13) -> Product spill | H19: =_xlfn.XLOOKUP(H18,'Downtime factors'!$A$2:$A$13,'Downtime factors'!$B$2:$B$13) -> Machine adjustment | I19: =_xlfn.XLOOKUP(I18,'Downtime factors'!$A$2:$A$13,'Downtime factors'!$B$2:$B$13) -> Machine failure | J19: =_xlfn.XLOOKUP(J18,'Downtime factors'!$A$2:$A$13,'Downtime factors'!$B$2:$B$13) -> Batch coding error | K19: =_xlfn.XLOOKUP(K18,'Downtime factors'!$A$2:$A$13,'Downtime factors'!$B$2:$B$13) -> Conveyor belt jam | ... N19: =_xlfn.XLOOKUP(N18,'Downtime factors'!$A$2:$A$13,'Downtime factors'!$B$2:$B$13) -> Other | O19: TOTAL
B20: {=_xlfn.UNIQUE('Line downtime'!N3:N40)} -> Mac | D20: {=SUMPRODUCT(('Line downtime'!$N$3:$N$40=$B20)*('Line downtime'!$B$2:$M$2=D$18)*'Line downtime'!$B$3:$M$40)} -> 130 | E20: {=SUMPRODUCT(('Line downtime'!$N$3:$N$40=$B20)*('Line downtime'!$B$2:$M$2=E$18)*'Line downtime'!$B$3:$M$40)} -> 0 | F20: {=SUMPRODUCT(('Line downtime'!$N$3:$N$40=$B20)*('Line downtime'!$B$2:$M$2=F$18)*'Line downtime'!$B$3:$M$40)} -> 80 | G20: {=SUMPRODUCT(('Line downtime'!$N$3:$N$40=$B20)*('Line downtime'!$B$2:$M$2=G$18)*'Line downtime'!$B$3:$M$40)} -> 0 | H20: {=SUMPRODUCT(('Line downtime'!$N$3:$N$40=$B20)*('Line downtime'!$B$2:$M$2=H$18)*'Line downtime'!$B$3:$M$40)} -> 15 | I20: {=SUMPRODUCT(('Line downtime'!$N$3:$N$40=$B20)*('Line downtime'!$B$2:$M$2=I$18)*'Line downtime'!$B$3:$M$40)} -> 45 | J20: {=SUMPRODUCT(('Line downtime'!$N$3:$N$40=$B20)*('Line downtime'!$B$2:$M$2=J$18)*'Line downtime'!$B$3:$M$40)} -> 47 | K20: {=SUMPRODUCT(('Line downtime'!$N$3:$N$40=$B20)*('Line downtime'!$B$2:$M$2=K$18)*'Line downtime'!$B$3:$M$40)} -> 0 | ... N20: {=SUMPRODUCT(('Line downtime'!$N$3:$N$40=$B20)*('Line downtime'!$B$2:$M$2=N$18)*'Line downtime'!$B$3:$M$40)} -> 15 | O20: =SUM(D20:N20) -> 332
B21: Charlie | D21: {=SUMPRODUCT(('Line downtime'!$N$3:$N$40=$B21)*('Line downtime'!$B$2:$M$2=D$18)*'Line downtime'!$B$3:$M$40)} -> 10 | E21: {=SUMPRODUCT(('Line downtime'!$N$3:$N$40=$B21)*('Line downtime'!$B$2:$M$2=E$18)*'Line downtime'!$B$3:$M$40)} -> 22 | F21: {=SUMPRODUCT(('Line downtime'!$N$3:$N$40=$B21)*('Line downtime'!$B$2:$M$2=F$18)*'Line downtime'!$B$3:$M$40)} -> 17 | G21: {=SUMPRODUCT(('Line downtime'!$N$3:$N$40=$B21)*('Line downtime'!$B$2:$M$2=G$18)*'Line downtime'!$B$3:$M$40)} -> 22 | H21: {=SUMPRODUCT(('Line downtime'!$N$3:$N$40=$B21)*('Line downtime'!$B$2:$M$2=H$18)*'Line downtime'!$B$3:$M$40)} -> 118 | I21: {=SUMPRODUCT(('Line downtime'!$N$3:$N$40=$B21)*('Line downtime'!$B$2:$M$2=I$18)*'Line downtime'!$B$3:$M$40)} -> 85 | J21: {=SUMPRODUCT(('Line downtime'!$N$3:$N$40=$B21)*('Line downtime'!$B$2:$M$2=J$18)*'Line downtime'!$B$3:$M$40)} -> 44 | K21: {=SUMPRODUCT(('Line downtime'!$N$3:$N$40=$B21)*('Line downtime'!$B$2:$M$2=K$18)*'Line downtime'!$B$3:$M$40)} -> 0 | ... N21: {=SUMPRODUCT(('Line downtime'!$N$3:$N$40=$B21)*('Line downtime'!$B$2:$M$2=N$18)*'Line downtime'!$B$3:$M$40)} -> 32 | O21: =SUM(D21:N21) -> 384
B22: Dee | D22: {=SUMPRODUCT(('Line downtime'!$N$3:$N$40=$B22)*('Line downtime'!$B$2:$M$2=D$18)*'Line downtime'!$B$3:$M$40)} -> 20 | E22: {=SUMPRODUCT(('Line downtime'!$N$3:$N$40=$B22)*('Line downtime'!$B$2:$M$2=E$18)*'Line downtime'!$B$3:$M$40)} -> 20 | F22: {=SUMPRODUCT(('Line downtime'!$N$3:$N$40=$B22)*('Line downtime'!$B$2:$M$2=F$18)*'Line downtime'!$B$3:$M$40)} -> 85 | G22: {=SUMPRODUCT(('Line downtime'!$N$3:$N$40=$B22)*('Line downtime'!$B$2:$M$2=G$18)*'Line downtime'!$B$3:$M$40)} -> 15 | H22: {=SUMPRODUCT(('Line downtime'!$N$3:$N$40=$B22)*('Line downtime'!$B$2:$M$2=H$18)*'Line downtime'!$B$3:$M$40)} -> 79 | I22: {=SUMPRODUCT(('Line downtime'!$N$3:$N$40=$B22)*('Line downtime'!$B$2:$M$2=I$18)*'Line downtime'!$B$3:$M$40)} -> 36 | J22: {=SUMPRODUCT(('Line downtime'!$N$3:$N$40=$B22)*('Line downtime'!$B$2:$M$2=J$18)*'Line downtime'!$B$3:$M$40)} -> 30 | K22: {=SUMPRODUCT(('Line downtime'!$N$3:$N$40=$B22)*('Line downtime'!$B$2:$M$2=K$18)*'Line downtime'!$B$3:$M$40)} -> 17 | ... N22: {=SUMPRODUCT(('Line downtime'!$N$3:$N$40=$B22)*('Line downtime'!$B$2:$M$2=N$18)*'Line downtime'!$B$3:$M$40)} -> 20 | O22: =SUM(D22:N22) -> 370
B23: Dennis | D23: {=SUMPRODUCT(('Line downtime'!$N$3:$N$40=$B23)*('Line downtime'!$B$2:$M$2=D$18)*'Line downtime'!$B$3:$M$40)} -> 0 | E23: {=SUMPRODUCT(('Line downtime'!$N$3:$N$40=$B23)*('Line downtime'!$B$2:$M$2=E$18)*'Line downtime'!$B$3:$M$40)} -> 0 | F23: {=SUMPRODUCT(('Line downtime'!$N$3:$N$40=$B23)*('Line downtime'!$B$2:$M$2=F$18)*'Line downtime'!$B$3:$M$40)} -> 43 | G23: {=SUMPRODUCT(('Line downtime'!$N$3:$N$40=$B23)*('Line downtime'!$B$2:$M$2=G$18)*'Line downtime'!$B$3:$M$40)} -> 20 | H23: {=SUMPRODUCT(('Line downtime'!$N$3:$N$40=$B23)*('Line downtime'!$B$2:$M$2=H$18)*'Line downtime'!$B$3:$M$40)} -> 120 | I23: {=SUMPRODUCT(('Line downtime'!$N$3:$N$40=$B23)*('Line downtime'!$B$2:$M$2=I$18)*'Line downtime'!$B$3:$M$40)} -> 88 | J23: {=SUMPRODUCT(('Line downtime'!$N$3:$N$40=$B23)*('Line downtime'!$B$2:$M$2=J$18)*'Line downtime'!$B$3:$M$40)} -> 24 | K23: {=SUMPRODUCT(('Line downtime'!$N$3:$N$40=$B23)*('Line downtime'!$B$2:$M$2=K$18)*'Line downtime'!$B$3:$M$40)} -> 0 | ... N23: {=SUMPRODUCT(('Line downtime'!$N$3:$N$40=$B23)*('Line downtime'!$B$2:$M$2=N$18)*'Line downtime'!$B$3:$M$40)} -> 7 | O23: =SUM(D23:N23) -> 302
D24: =SUM(D20:D23) -> 160 | E24: =SUM(E20:E23) -> 42 | F24: =SUM(F20:F23) -> 225 | G24: =SUM(G20:G23) -> 57 | H24: =SUM(H20:H23) -> 332 | I24: =SUM(I20:I23) -> 254 | J24: =SUM(J20:J23) -> 145 | K24: =SUM(K20:K23) -> 17 | ... N24: =SUM(N20:N23) -> 74

Sheet Line productivity
A1: Date | B1: Product | C1: Batch | D1: Operator | E1: Start Time | F1: End Time | G1: Time Taken | H1: Min Batch Time | I1: Efficiency (%)
A2: 45533 | B2: OR-600 | C2: 422111 | D2: Mac | E2: 0.49305556 | F2: 0.58680556 | G2: =(F2-E2)*1440 -> 135 | H2: =_xlfn.XLOOKUP(B2,Products!$A$2:$A$7,Products!$D$2:$D$7) -> 60 | I2: =(H2/G2)*100 -> 44.444444
A3: 45533 | B3: LE-600 | C3: 422112 | D3: Mac | E3: 0.58680556 | F3: 0.65625 | G3: =(F3-E3)*1440 -> 100 | H3: =_xlfn.XLOOKUP(B3,Products!$A$2:$A$7,Products!$D$2:$D$7) -> 60 | I3: =(H3/G3)*100 -> 60
A4: 45533 | B4: LE-600 | C4: 422113 | D4: Mac | E4: 0.65625 | F4: 0.73263889 | G4: =(F4-E4)*1440 -> 110 | H4: =_xlfn.XLOOKUP(B4,Products!$A$2:$A$7,Products!$D$2:$D$7) -> 60 | I4: =(H4/G4)*100 -> 54.545455
A5: 45533 | B5: LE-600 | C5: 422114 | D5: Mac | E5: 0.73263889 | F5: 0.80208333 | G5: =(F5-E5)*1440 -> 100 | H5: =_xlfn.XLOOKUP(B5,Products!$A$2:$A$7,Products!$D$2:$D$7) -> 60 | I5: =(H5/G5)*100 -> 60
A6: 45533 | B6: LE-600 | C6: 422115 | D6: Charlie | E6: 0.80208333 | F6: 0.86041667 | G6: =(F6-E6)*1440 -> 84 | H6: =_xlfn.XLOOKUP(B6,Products!$A$2:$A$7,Products!$D$2:$D$7) -> 60 | I6: =(H6/G6)*100 -> 71.428571
A7: 45533 | B7: LE-600 | C7: 422116 | D7: Charlie | E7: 0.86041667 | F7: 0.90208333 | G7: =(F7-E7)*1440 -> 60 | H7: =_xlfn.XLOOKUP(B7,Products!$A$2:$A$7,Products!$D$2:$D$7) -> 60 | I7: =(H7/G7)*100 -> 100
A8: 45533 | B8: LE-600 | C8: 422117 | D8: Charlie | E8: 0.90208333 | F8: 0.95416667 | G8: =(F8-E8)*1440 -> 75 | H8: =_xlfn.XLOOKUP(B8,Products!$A$2:$A$7,Products!$D$2:$D$7) -> 60 | I8: =(H8/G8)*100 -> 80
A9: 45534 | B9: CO-600 | C9: 422118 | D9: Dee | E9: 0.17013889 | F9: 0.25347222 | G9: =(F9-E9)*1440 -> 120 | H9: =_xlfn.XLOOKUP(B9,Products!$A$2:$A$7,Products!$D$2:$D$7) -> 60 | I9: =(H9/G9)*100 -> 50
A10: 45534 | B10: CO-600 | C10: 422119 | D10: Dee | E10: 0.25347222 | F10: 0.3125 | G10: =(F10-E10)*1440 -> 85 | H10: =_xlfn.XLOOKUP(B10,Products!$A$2:$A$7,Products!$D$2:$D$7) -> 60 | I10: =(H10/G10)*100 -> 70.588235
A11: 45534 | B11: CO-600 | C11: 422120 | D11: Dee | E11: 0.3125 | F11: 0.39027778 | G11: =(F11-E11)*1440 -> 112 | H11: =_xlfn.XLOOKUP(B11,Products!$A$2:$A$7,Products!$D$2:$D$7) -> 60 | I11: =(H11/G11)*100 -> 53.571429
A12: 45534 | B12: CO-600 | C12: 422121 | D12: Dennis | E12: 0.39027778 | F12: 0.44236111 | G12: =(F12-E12)*1440 -> 75 | H12: =_xlfn.XLOOKUP(B12,Products!$A$2:$A$7,Products!$D$2:$D$7) -> 60 | I12: =(H12/G12)*100 -> 80
A13: 45534 | B13: CO-600 | C13: 422122 | D13: Dennis | E13: 0.44236111 | F13: 0.50138889 | G13: =(F13-E13)*1440 -> 85 | H13: =_xlfn.XLOOKUP(B13,Products!$A$2:$A$7,Products!$D$2:$D$7) -> 60 | I13: =(H13/G13)*100 -> 70.588235
... A39: 45538 | B39: CO-2L | C39: 422148 | D39: Mac | E39: 0.95486111 | F39: 1.0451389 | G39: =(F39-E39)*1440 -> 130 | H39: =_xlfn.XLOOKUP(B39,Products!$A$2:$A$7,Products!$D$2:$D$7) -> 98 | I39: =(H39/G39)*100 -> 75.384615
I41: =AVERAGE(I2:I39) -> 67.076697

Sheet EFFICIENCY 
A1: EFFICIENCY BY OPERATOR | H1: EFFICIENCY BY PRODUCT
A2: OPERATOR | B2: AVERAGE EFFICIENCY | H2: PRODUCT | I2: AVERAGE EFFICIENCY
A3: {=_xlfn.UNIQUE('Line productivity'!D2:D39)} -> Mac | B3: =AVERAGEIF('Line productivity'!D2:D39,'EFFICIENCY '!A3,'Line productivity'!I2:I39) -> 63.257853 | H3: {=_xlfn.UNIQUE('Line productivity'!B2:B39)} -> OR-600 | I3: =AVERAGEIF('Line productivity'!B2:B39,'EFFICIENCY '!H3,'Line productivity'!I2:I39) -> 44.444444
A4: Charlie | B4: =AVERAGEIF('Line productivity'!D5:D42,'EFFICIENCY '!A6,'Line productivity'!I5:I42) -> 65.905133 | H4: LE-600 | I4: =AVERAGEIF('Line productivity'!B3:B40,'EFFICIENCY '!H4,'Line productivity'!I3:I40) -> 70.995671
A5: Dee | B5: =AVERAGEIF('Line productivity'!D4:D41,'EFFICIENCY '!A5,'Line productivity'!I4:I41) -> 66.809779 | H5: CO-600 | I5: =AVERAGEIF('Line productivity'!B4:B41,'EFFICIENCY '!H5,'Line productivity'!I4:I41) -> 67.338683
A6: Dennis | B6: =AVERAGEIF('Line productivity'!D3:D40,'EFFICIENCY '!A4,'Line productivity'!I3:I40) -> 70.973001 | H6: DC-600 | I6: =AVERAGEIF('Line productivity'!B5:B42,'EFFICIENCY '!H6,'Line productivity'!I5:I42) -> 71.672078
H7: RB-600 | I7: =AVERAGEIF('Line productivity'!B6:B43,'EFFICIENCY '!H7,'Line productivity'!I6:I43) -> 64.449658
A8: AVERAGE | B8: =AVERAGE(B3:B6) -> 66.736442 | H8: CO-2L | I8: =AVERAGEIF('Line productivity'!B7:B44,'EFFICIENCY '!H8,'Line productivity'!I7:I44) -> 66.115969

Sheet Products
A1: Product | B1: Flavor | C1: Size | D1: Min batch time
A2: OR-600 | B2: Orange | C2: 600 ml | D2: 60
A3: LE-600 | B3: Lemon lime | C3: 600 ml | D3: 60
A4: CO-600 | B4: Cola | C4: 600 ml | D4: 60
A5: DC-600 | B5: Diet Cola | C5: 600 ml | D5: 60
A6: RB-600 | B6: Root Beer | C6: 600 ml | D6: 60
A7: CO-2L | B7: Cola | C7: 2 L | D7: 98

Sheet Downtime factors
A1: Factor | B1: Description | C1: Operator Error
A2: 1 | B2: Emergency stop | C2: No
A3: 2 | B3: Batch change | C3: Yes
A4: 3 | B4: Labeling error | C4: No
A5: 4 | B5: Inventory shortage | C5: No
A6: 5 | B6: Product spill | C6: Yes
A7: 6 | B7: Machine adjustment | C7: Yes
A8: 7 | B8: Machine failure | C8: No
A9: 8 | B9: Batch coding error | C9: Yes
A10: 9 | B10: Conveyor belt jam | C10: No
A11: 10 | B11: Calibration error | C11: Yes
A12: 11 | B12: Label switch | C12: Yes
A13: 12 | B13: Other | C13: No

Sheet Line downtime
B1: Downtime factor
A2: Batch | B2: 1 | C2: 2 | D2: 3 | E2: 4 | F2: 5 | G2: 6 | H2: 7 | I2: 8 | J2: 9 | K2: 10 | L2: 11 | M2: 12 | N2: OPERATOR
A3: 422111 | C3: 60 | H3: 15 | N3: =_xlfn.XLOOKUP('Line downtime'!A3,'Line productivity'!C2:C39,'Line productivity'!D2:D39) -> Mac
A4: 422112 | C4: 20 | I4: 20 | N4: =_xlfn.XLOOKUP('Line downtime'!A4,'Line productivity'!C3:C40,'Line productivity'!D3:D40) -> Mac
A5: 422113 | C5: 50 | N5: =_xlfn.XLOOKUP('Line downtime'!A5,'Line productivity'!C4:C41,'Line productivity'!D4:D41) -> Mac
A6: 422114 | E6: 25 | G6: 15 | N6: =_xlfn.XLOOKUP('Line downtime'!A6,'Line productivity'!C5:C42,'Line productivity'!D5:D42) -> Mac
A7: 422115 | K7: 24 | N7: =_xlfn.XLOOKUP('Line downtime'!A7,'Line productivity'!C6:C43,'Line productivity'!D6:D43) -> Charlie
A8: 422116 | N8: =_xlfn.XLOOKUP('Line downtime'!A8,'Line productivity'!C7:C44,'Line productivity'!D7:D44) -> Charlie
A9: 422117 | C9: 10 | G9: 5 | N9: =_xlfn.XLOOKUP('Line downtime'!A9,'Line productivity'!C8:C45,'Line productivity'!D8:D45) -> Charlie
A10: 422118 | G10: 14 | H10: 16 | L10: 10 | M10: 20 | N10: =_xlfn.XLOOKUP('Line downtime'!A10,'Line productivity'!C9:C46,'Line productivity'!D9:D46) -> Dee
A11: 422119 | E11: 25 | N11: =_xlfn.XLOOKUP('Line downtime'!A11,'Line productivity'!C10:C47,'Line productivity'!D10:D47) -> Dee
A12: 422120 | E12: 20 | F12: 15 | J12: 17 | N12: =_xlfn.XLOOKUP('Line downtime'!A12,'Line productivity'!C11:C48,'Line productivity'!D11:D48) -> Dee
A13: 422121 | H13: 15 | N13: =_xlfn.XLOOKUP('Line downtime'!A13,'Line productivity'!C12:C49,'Line productivity'!D12:D49) -> Dennis
A14: 422122 | H14: 25 | N14: =_xlfn.XLOOKUP('Line downtime'!A14,'Line productivity'!C13:C50,'Line productivity'!D13:D50) -> Dennis
A15: 422123 | E15: 43 | H15: 30 | N15: =_xlfn.XLOOKUP('Line downtime'!A15,'Line productivity'!C14:C51,'Line productivity'!D14:D51) -> Dennis
A16: 422124 | F16: 20 | G16: 20 | N16: =_xlfn.XLOOKUP('Line downtime'!A16,'Line productivity'!C15:C52,'Line productivity'!D15:D52) -> Dennis
A17: 422125 | L17: 10 | M17: 10 | N17: =_xlfn.XLOOKUP('Line downtime'!A17,'Line productivity'!C16:C53,'Line productivity'!D16:D53) -> Charlie
A18: 422126 | I18: 44 | N18: =_xlfn.XLOOKUP('Line downtime'!A18,'Line productivity'!C17:C54,'Line productivity'!D17:D54) -> Charlie
A19: 422127 | G19: 23 | N19: =_xlfn.XLOOKUP('Line downtime'!A19,'Line productivity'!C18:C55,'Line productivity'!D18:D55) -> Charlie
A20: 422128 | F20: 22 | H20: 30 | N20: =_xlfn.XLOOKUP('Line downtime'!A20,'Line productivity'!C19:C56,'Line productivity'!D19:D56) -> Charlie
A21: 422129 | M21: 15 | N21: =_xlfn.XLOOKUP('Line downtime'!A21,'Line productivity'!C20:C57,'Line productivity'!D20:D57) -> Charlie
A22: 422130 | C22: 20 | N22: =_xlfn.XLOOKUP('Line downtime'!A22,'Line productivity'!C21:C58,'Line productivity'!D21:D58) -> Dee
A23: 422131 | E23: 20 | K23: 10 | N23: =_xlfn.XLOOKUP('Line downtime'!A23,'Line productivity'!C22:C59,'Line productivity'!D22:D59) -> Dee
A24: 422132 | N24: =_xlfn.XLOOKUP('Line downtime'!A24,'Line productivity'!C23:C60,'Line productivity'!D23:D60) -> Dee
A25: 422133 | H25: 20 | N25: =_xlfn.XLOOKUP('Line downtime'!A25,'Line productivity'!C24:C61,'Line productivity'!D24:D61) -> Dee
A26: 422134 | H26: 30 | I26: 20 | N26: =_xlfn.XLOOKUP('Line downtime'!A26,'Line productivity'!C25:C62,'Line productivity'!D25:D62) -> Mac
A27: 422135 | E27: 30 | M27: 15 | N27: =_xlfn.XLOOKUP('Line downtime'!A27,'Line productivity'!C26:C63,'Line productivity'!D26:D63) -> Mac
A28: 422136 | N28: =_xlfn.XLOOKUP('Line downtime'!A28,'Line productivity'!C27:C64,'Line productivity'!D27:D64) -> Mac
A29: 422137 | I29: 30 | K29: 15 | N29: =_xlfn.XLOOKUP('Line downtime'!A29,'Line productivity'!C28:C65,'Line productivity'!D28:D65) -> Dee
A30: 422138 | D30: 20 | N30: =_xlfn.XLOOKUP('Line downtime'!A30,'Line productivity'!C29:C66,'Line productivity'!D29:D66) -> Dee
A31: 422139 | E31: 20 | G31: 15 | N31: =_xlfn.XLOOKUP('Line downtime'!A31,'Line productivity'!C30:C67,'Line productivity'!D30:D67) -> Dee
A32: 422140 | G32: 50 | L32: 13 | N32: =_xlfn.XLOOKUP('Line downtime'!A32,'Line productivity'!C31:C68,'Line productivity'!D31:D68) -> Dee
A33: 422141 | M33: 7 | N33: =_xlfn.XLOOKUP('Line downtime'!A33,'Line productivity'!C32:C69,'Line productivity'!D32:D69) -> Dennis
A34: 422142 | G34: 30 | N34: =_xlfn.XLOOKUP('Line downtime'!A34,'Line productivity'!C33:C70,'Line productivity'!D33:D70) -> Dennis
A35: 422143 | G35: 40 | H35: 18 | N35: =_xlfn.XLOOKUP('Line downtime'!A35,'Line productivity'!C34:C71,'Line productivity'!D34:D71) -> Dennis
A36: 422144 | G36: 30 | I36: 24 | N36: =_xlfn.XLOOKUP('Line downtime'!A36,'Line productivity'!C35:C72,'Line productivity'!D35:D72) -> Dennis
A37: 422145 | D37: 22 | N37: =_xlfn.XLOOKUP('Line downtime'!A37,'Line productivity'!C36:C73,'Line productivity'!D36:D73) -> Charlie
A38: 422146 | G38: 30 | H38: 25 | M38: 7 | N38: =_xlfn.XLOOKUP('Line downtime'!A38,'Line productivity'!C37:C74,'Line productivity'!D37:D74) -> Charlie
A39: 422147 | E39: 17 | G39: 60 | H39: 30 | N39: =_xlfn.XLOOKUP('Line downtime'!A39,'Line productivity'!C38:C75,'Line productivity'!D38:D75) -> Charlie
A40: 422148 | E40: 25 | I40: 7 | N40: =_xlfn.XLOOKUP('Line downtime'!A40,'Line productivity'!C39:C76,'Line productivity'!D39:D76) -> Mac
...
